<?xml version="1.0" ?>

<robot name="boldbot" xmlns:xacro="http://www.ros.org/wiki/xacro">
  <!-- PLA: 1.24 g/cm^3 -->
  <xacro:property name="filament_density_full" value="1240" />
  <xacro:property name="infill" value=".5" />
  <xacro:property name="filament_density" value="${filament_density_full * infill}" />

  <xacro:macro name="xmass" params="value"><mass value="${value}" /></xacro:macro>
  <!-- <xacro:macro name="xmass" params="value"><mass value="1" /></xacro:macro> -->

  <xacro:macro name="inertial_cuboid" params="mass xyz x_length y_length z_length">
    <inertial>
      <xacro:xmass value="${mass}" />
      <origin xyz="${xyz}" />
      <inertia ixx="${mass * (y_length*y_length + z_length*z_length) / 12}" ixy="0.0" ixz="0.0"
               iyy="${mass * (x_length*x_length + z_length*z_length) / 12}" iyz="0.0"
               izz="${mass * (x_length*x_length + y_length*y_length) / 12}" />
    </inertial>
  </xacro:macro>

  <!-- <xacro:macro name="inertial_cuboid" params="mass xyz x_length y_length z_length"> -->
  <!--   <inertial> -->
  <!--     <xacro:xmass value="1" /> -->
  <!--     <origin xyz="${xyz}" /> -->
  <!--     <inertia ixx="${1 * (y_length*y_length + z_length*z_length) / 12}" ixy="0.0" ixz="0.0" -->
  <!--              iyy="${1 * (x_length*x_length + z_length*z_length) / 12}" iyz="0.0" -->
  <!--              izz="${1 * (x_length*x_length + y_length*y_length) / 12}" /> -->
  <!--   </inertial> -->
  <!-- </xacro:macro> -->

  <xacro:macro name="mx28" params="name xyz rpy">
    <link name="${name}">
      <visual>
        <origin xyz="${xyz}" rpy="${rpy}" />
        <geometry>
          <mesh filename="package://boldbot_description/meshes/mx28b.stl" scale="0.001 0.001 0.001" />
        </geometry>
        <material name="DarkGrey">
          <color rgba="0.20 0.20 0.20 1.0"/>
        </material>
      </visual>
      <collision>
        <origin xyz="${xyz}" rpy="${rpy}" />
        <geometry>
          <mesh filename="package://boldbot_description/meshes/mx28b.stl" scale="0.001 0.001 0.001" />
        </geometry>
      </collision>
      <xacro:inertial_cuboid mass="0.077" x_length="0.0506" y_length="0.0356" z_length="0.0355" />
    </link>
    <gazebo reference="${name}">
      <material>Gazebo/DarkGrey</material>
      <selfCollide>true</selfCollide>
    </gazebo>
  </xacro:macro>

  <!-- dummy first link, directly connects with torso -->
  <link name="base_link" />

  <joint name="base_joint" type="fixed">
    <child link="torso"/>
    <parent link="base_link"/>
    <origin xyz="0 0 0" rpy="0 0 0" />
  </joint>

  <link name="torso">
    <visual>
      <origin rpy="0 0 0" xyz="0 0 0" />
      <geometry>
        <box size="0.1 0.109 0.045"/>
      </geometry>
    </visual>
    <collision>
      <origin rpy="0 0 0" xyz="0 0 0" />
      <geometry>
        <box size="0.1 0.109 0.045"/>
      </geometry>
    </collision>
    <xacro:inertial_cuboid mass="0.31" x_length="0.1" y_length="0.109" z_length="0.045"/>
  </link>
  <gazebo reference="torso">
    <material>Gazebo/Grey</material>
    <selfCollide>true</selfCollide>
  </gazebo>

  <joint name="torso-mx28-head-pan" type="fixed">
    <parent link="torso" />
    <child link="mx28-head-pan" />
    <origin rpy="0 0 0" xyz="0.02 0 0.045" />
  </joint>

  <xacro:mx28 name="mx28-head-pan" xyz="0 0 0" rpy="0 0 3.141592654"/>

  <joint name="head-pan" type="revolute">
    <parent link="mx28-head-pan" />
    <child link="neck" />
    <origin rpy="0 0 0" xyz="0 0 0" />
    <axis xyz="0 0 1" />
    <limit effort="2.8" velocity="5.6548668" lower="-2.6179939" upper="2.6179939" />
  </joint>

  <link name="neck">
    <visual>
      <origin rpy="0 0 0" xyz="0 0 0.03" />
      <geometry>
        <box size="0.01 0.01 0.01"/>
      </geometry>
    </visual>
    <inertial>
      <origin xyz="0 0 0" />
      <mass value="1e-3"/>
      <inertia ixx="1e-4"  ixy="0.0"  ixz="0.0" iyy="1e-4" iyz="0.0" izz="1e-4" />
    </inertial>
  </link>

  <joint name="head-tilt" type="revolute">
    <parent link="neck" />
    <child link="mx28-head-tilt" />
    <origin xyz="0 0 0.05" />
    <axis xyz="0 1 0" />
    <limit effort="2.8" velocity="5.6548668" lower="-2.6179939" upper="2.6179939" />
  </joint>

  <xacro:mx28 name="mx28-head-tilt" xyz="0 0 0" rpy="0 -1.570796327 -1.570796327"/>

  <joint name="head-tilt-head" type="fixed">
    <parent link="mx28-head-tilt" />
    <child link="head" />
    <origin rpy="0 0 0" xyz="0 0 0.065" />
  </joint>

  <link name="head">
    <visual>
      <origin rpy="0 0 0" xyz="0 0 0"/>
      <geometry>
        <box size="0.05 0.1 0.04" />
      </geometry>
    </visual>
    <collision>
      <origin rpy="0 0 0" xyz="0 0 0"/>
      <geometry>
        <box size="0.05 0.1 0.04" />
      </geometry>
    </collision>
    <inertial>
      <origin xyz="0 0 0" />
      <mass value=".2"/>
      <inertia ixx="1e-3"  ixy="0.0"  ixz="0.0" iyy="1e-3" iyz="0.0" izz="1e-3" />
    </inertial>
  </link>
  <gazebo reference="head">
    <material>Gazebo/Grey</material>
    <selfCollide>true</selfCollide>
  </gazebo>

  <!-- Arms -->

  <xacro:macro name="arm" params="side">
    <xacro:property name="lr" value="${1 if side == 'l' else -1}" />

    <joint name="torso-mx28-shoulder-pitch-${side}" type="fixed">
      <parent link="torso" />
      <child link="mx28-shoulder-pitch-${side}" />
      <origin xyz="0.02 ${lr * 0.04} 0.045" />
    </joint>

    <xacro:mx28 name="mx28-shoulder-pitch-${side}" xyz="0 0 0" rpy="${lr * 1.570796327} 0 3.141592654"/>

    <joint name="shoulder-pitch-${side}" type="revolute">
      <parent link="mx28-shoulder-pitch-${side}" />
      <child link="shoulder-${side}" />
      <origin rpy="0 0 0" xyz="0 0 0" />
      <axis xyz="0 ${lr} 0" />
      <limit effort="2.8" velocity="5.6548668" lower="-2.6179939" upper="2.6179939" />
    </joint>

    <link name="shoulder-${side}">
      <visual>
        <origin rpy="0 0 0" xyz="0 ${lr * 0.021} -0.008" />
        <geometry>
          <box size="0.01 0.01 0.01"/>
        </geometry>
      </visual>
      <inertial>
        <origin xyz="0 0 0" />
        <xacro:xmass value="0.1"/>
        <inertia ixx="1e-4"  ixy="0.0"  ixz="0.0" iyy="1e-4" iyz="0.0" izz="1e-4" />
      </inertial>
    </link>

    <joint name="shoulder-roll-${side}" type="revolute">
      <parent link="shoulder-${side}" />
      <child link="mx28-shoulder-roll-${side}" />
      <origin xyz="0 ${lr * 0.042} -0.016" rpy="${lr * 0.785398163} 0 0" />
      <axis xyz="1 0 0" />
      <limit effort="2.8" velocity="5.6548668" lower="-2.6179939" upper="2.6179939" />
    </joint>

    <xacro:mx28 name="mx28-shoulder-roll-${side}" xyz="0 0 0" rpy="0 1.570796327 0"/>

    <joint name="mx28-shoulder-roll-${side}-mx28-elbow-${side}" type="fixed">
      <parent link="mx28-shoulder-roll-${side}" />
      <child link="mx28-elbow-${side}" />
      <origin xyz="0.016 0 -0.06" />
    </joint>

    <xacro:mx28 name="mx28-elbow-${side}" xyz="0 0 0" rpy="${lr * 1.570796327} 0 3.141592654"/>

    <joint name="elbow-${side}" type="revolute">
      <parent link="mx28-elbow-${side}" />
      <child link="lower-arm-${side}" />
      <origin xyz="0 0 0" rpy="0 0 0"/>
      <axis xyz="0 ${lr} 0" />
      <limit effort="2.8" velocity="5.6548668" lower="-2.6179939" upper="2.6179939" />
    </joint>

    <link name="lower-arm-${side}">
      <visual>
        <origin xyz="0.055 ${lr * 0.02} -0.02" rpy="${lr * 1.570796327} 0 0" />
        <geometry>
          <mesh filename="package://boldbot_description/meshes/armcoverb.stl" scale="0.001 0.001 0.001"/>
        </geometry>
      </visual>
      <collision>
        <origin xyz="0.055 ${lr * 0.02} -0.02" rpy="${lr * 1.570796327} 0 0" />
        <geometry>
          <mesh filename="package://boldbot_description/meshes/armcoverb.stl" scale="0.001 0.001 0.001"/>
        </geometry>
      </collision>
      <inertial>
        <origin xyz="0 0 0" />
        <xacro:xmass value="0.1"/>
        <inertia ixx="1e-3"  ixy="0.0"  ixz="0.0" iyy="1e-3" iyz="0.0" izz="1e-3" />
      </inertial>
    </link>
    <gazebo reference="lower-arm-${side}">
      <material>Gazebo/Grey</material>
      <selfCollide>true</selfCollide>
    </gazebo>
  </xacro:macro>

  <xacro:arm side="l"/>
  <xacro:arm side="r"/>

  <!-- Legs -->

  <xacro:macro name="leg" params="side">
    <xacro:property name="lr" value="${1 if side == 'l' else -1}"/>

    <joint name="torso-mx28-hip-yaw-${side}" type="fixed">
      <parent link="torso" />
      <child link="mx28-hip-yaw-${side}" />
      <origin xyz="0.018 ${lr * 0.037} -0.04" />
    </joint>

    <xacro:mx28 name="mx28-hip-yaw-${side}" xyz="0 0 0" rpy="${lr * 3.141592654} 0 3.141592654"/>

    <joint name="hip-yaw-${side}" type="revolute">
      <parent link="mx28-hip-yaw-${side}" />
      <child link="hip-bracket-${side}" />
      <origin rpy="0 0 0" xyz="0 0 0" />
      <axis xyz="0 0 -1" />
      <limit effort="2.8" velocity="5.6548668" lower="-2.6179939" upper="2.6179939" />
    </joint>

    <link name="hip-bracket-${side}">
      <inertial>
        <origin xyz="0 0 0" />
        <xacro:xmass value=".1"/>
        <inertia ixx="1e-4"  ixy="0.0"  ixz="0.0" iyy="1e-4" iyz="0.0" izz="1e-4" />
      </inertial>
    </link>

    <joint name="hip-roll-${side}" type="revolute">
      <parent link="hip-bracket-${side}" />
      <child link="mx28-hip-roll-${side}" />
      <origin rpy="0 0 0" xyz="-0.05 0 -0.04" /> <!-- TODO: guessed -->
      <axis xyz="-1 0 0" />
      <limit effort="2.8" velocity="5.6548668" lower="-2.6179939" upper="2.6179939" />
    </joint>

    <xacro:mx28 name="mx28-hip-roll-${side}" xyz="0 0 0" rpy="0 1.570796327 0"/>

    <joint name="mx28-hip-roll-mx28-hip-pitch-${side}" type="fixed">
      <parent link="mx28-hip-roll-${side}" />
      <child link="mx28-hip-pitch-${side}" />
      <origin xyz="0.05 0 0" rpy="0 0 0" />
    </joint>

    <xacro:mx28 name="mx28-hip-pitch-${side}" xyz="0 0 0" rpy="1.570796327 1.570796327 0"/>

    <joint name="hip-pitch-${side}" type="revolute">
      <parent link="mx28-hip-pitch-${side}" />
      <child link="upper-leg-${side}" />
      <origin xyz="0 0 0" rpy="0 0 0" />
      <axis xyz="0 ${lr * -1} 0" />
      <limit effort="2.8" velocity="5.6548668" lower="-2.6179939" upper="2.6179939" />
    </joint>

    <link name="upper-leg-${side}">
      <visual>
        <origin xyz="0 0 0" rpy="0 1.570796327 0" />
        <geometry>
          <mesh filename="package://boldbot_description/meshes/thighb.stl" scale="0.001 0.001 0.001"/>
        </geometry>
      </visual>
      <collision>
        <origin xyz="0 0 0" rpy="0 1.570796327 0" />
        <geometry>
          <mesh filename="package://boldbot_description/meshes/thighb.stl" scale="0.001 0.001 0.001"/>
        </geometry>
      </collision>
      <inertial>
        <origin xyz="0 0 0" />
        <xacro:xmass value="0.1"/>
        <inertia ixx="1e-3"  ixy="0.0"  ixz="0.0" iyy="1e-3" iyz="0.0" izz="1e-3" />
      </inertial>
    </link>
    <gazebo reference="upper-leg-${side}">
      <material>Gazebo/Grey</material>
      <selfCollide>true</selfCollide>
    </gazebo>

    <joint name="upper-leg-mx28-knee-${side}" type="fixed">
      <parent link="upper-leg-${side}" />
      <child link="mx28-knee-${side}" />
      <origin xyz="0 0 -0.143" rpy="0 0 0" />
    </joint>

    <xacro:mx28 name="mx28-knee-${side}" xyz="0 0 0" rpy="1.570796327 -1.570796327 0"/>

    <joint name="knee-${side}" type="revolute">
      <parent link="mx28-knee-${side}" />
      <child link="lower-leg-${side}" />
      <origin xyz="0 0 0" rpy="0 0 0" />
      <axis xyz="0 ${lr * -1} 0" />
      <limit effort="2.8" velocity="5.6548668" lower="-2.6179939" upper="2.6179939" />
    </joint>

    <link name="lower-leg-${side}">
      <visual>
        <origin xyz="0.0175 0 -0.019" rpy="3.141592654 1.570796327 0" />
        <geometry>
          <mesh filename="package://boldbot_description/meshes/shinb.stl" scale="0.001 0.001 0.001"/>
        </geometry>
      </visual>
      <collision>
        <origin xyz="0.0175 0 -0.019" rpy="3.141592654 1.570796327 0" />
        <geometry>
          <mesh filename="package://boldbot_description/meshes/shinb.stl" scale="0.001 0.001 0.001"/>
        </geometry>
      </collision>
      <inertial>
	<origin xyz="0 0 0" />
	<mass value="0.1"/>
	<inertia ixx="1e-3"  ixy="0.0"  ixz="0.0" iyy="1e-3" iyz="0.0" izz="1e-3" />
      </inertial>
    </link>
    <gazebo reference="lower-leg-${side}">
      <material>Gazebo/Grey</material>
      <selfCollide>true</selfCollide>
    </gazebo>

    <joint name="ankle-pitch-${side}" type="revolute">
      <parent link="lower-leg-${side}" />
      <child link="mx28-ankle-pitch-${side}" />
      <origin xyz="0 0 -0.143" rpy="0 0 0" />
      <axis xyz="0 ${lr * 1} 0" />
      <limit effort="2.8" velocity="5.6548668" lower="-2.6179939" upper="2.6179939" />
    </joint>

    <xacro:mx28 name="mx28-ankle-pitch-${side}" xyz="0 0 0" rpy="1.570796327 -1.570796327 0"/>

    <joint name="mx28-ankle-pitch-mx28-ankle-roll-${side}" type="fixed">
      <parent link="mx28-ankle-pitch-${side}" />
      <child link="mx28-ankle-roll-${side}" />
      <origin xyz="-0.05 0 0" rpy="0 0 0" />
    </joint>

    <xacro:mx28 name="mx28-ankle-roll-${side}" xyz="0 0 0" rpy="3.141592654 -1.570796327 0"/>

    <joint name="ankle-roll-${side}" type="revolute">
      <parent link="mx28-ankle-roll-${side}" />
      <child link="foot-${side}" />
      <origin xyz="0 0 0" rpy="0 0 0" />
      <axis xyz="1 0 0" />
      <limit effort="2.8" velocity="5.6548668" lower="-2.6179939" upper="2.6179939" />
    </joint>

    <link name="foot-${side}">
      <visual>
        <origin xyz="0.05 ${lr * 0.01} -0.02" rpy="0 0 -1.570796327" /> <!-- TODO: guessed y offset -->
        <geometry>
          <mesh filename="package://boldbot_description/meshes/nicefoot${side}b.stl" scale="0.001 0.001 0.001"/>
        </geometry>
      </visual>
      <collision>
        <origin xyz="0.05 ${lr * 0.01} -0.02" rpy="0 0 -1.570796327" /> <!-- TODO: guessed y offset -->
        <geometry>
          <mesh filename="package://boldbot_description/meshes/nicefoot${side}b.stl" scale="0.001 0.001 0.001"/>
        </geometry>
      </collision>
      <inertial>
        <origin xyz="0 0 0" />
        <xacro:xmass value="0.1"/>
        <inertia ixx="1e-3"  ixy="0.0"  ixz="0.0" iyy="1e-3" iyz="0.0" izz="1e-3" />
      </inertial>
    </link>
    <gazebo reference="foot-${side}">
      <material>Gazebo/Grey</material>
      <selfCollide>true</selfCollide>
    </gazebo>
  </xacro:macro>

  <xacro:leg side="l"/>
  <xacro:leg side="r"/>

  <gazebo>
    <plugin name="boldbot_gazebo" filename="libboldbot_gazebo_plugin.so">
    </plugin>
  </gazebo>

  <gazebo reference="head">
    <sensor name='camera' type='camera'>
      <pose>0 0 0 0 0 0</pose>
      <camera name='__default__'>
        <horizontal_fov>1.012300</horizontal_fov>
        <image>
          <width>640</width>
          <height>480</height>
        </image>
        <clip>
          <near>0.001000</near>
          <far>100.000000</far>
        </clip>
      </camera>
      <always_on>1</always_on>
      <update_rate>30</update_rate>
      <visualize>true</visualize>
      <plugin name="camera_controller" filename="libgazebo_ros_camera.so">
        <alwaysOn>true</alwaysOn>
        <updateRate>30</updateRate>
        <cameraName>darwin/camera</cameraName>
        <imageTopicName>image_raw</imageTopicName>
        <cameraInfoTopicName>camera_info</cameraInfoTopicName>
        <frameName>camera_link</frameName>
        <hackBaseline>0.07</hackBaseline>
        <distortionK1>0.0</distortionK1>
        <distortionK2>0.0</distortionK2>
        <distortionK3>0.0</distortionK3>
        <distortionT1>0.0</distortionT1>
        <distortionT2>0.0</distortionT2>
      </plugin>
    </sensor>
  </gazebo>

 <gazebo reference="torso">
    <gravity>true</gravity>
    <sensor name="imu_sensor" type="imu">
      <always_on>true</always_on>
      <update_rate>125</update_rate>
      <!-- <visualize>true</visualize> -->
      <topic>__default_topic__</topic>
      <plugin filename="libgazebo_ros_imu_sensor.so" name="imu_plugin">
        <ros>
          <argument>~/out:=/imu/data_raw</argument>
        </ros>
        <bodyName>torso</bodyName>
        <gaussianNoise>0.0</gaussianNoise>
      </plugin>
      <pose>0 0 0 0 0 0</pose>
    </sensor>
  </gazebo>

</robot>
