<?xml version="1.0" ?>
<robot name="boldbot">
  <!-- dummy first link, directly connects with torso -->
  <link name="base_link" />

  <joint name="base_joint" type="fixed">
    <child link="torso"/>
    <parent link="base_link"/>
    <origin xyz="0 0 0" rpy="0 0 0" />
  </joint>

  <link name="torso">
    <visual>
      <origin rpy="0 0 0" xyz="0 0 -0.035" />
      <geometry>
        <box size="0.1 0.13 0.17"/>
      </geometry>
    </visual>
    <collision>
      <origin rpy="0 0 0" xyz="0 0 -0.035" />
      <geometry>
        <box size="0.1 0.13 0.17"/>
      </geometry>
    </collision>
    <inertial>
      <origin xyz="0 0 0" />
      <mass value="1"/>
      <inertia ixx="1e-3"  ixy="0.0"  ixz="0.0" iyy="1e-3" iyz="0.0" izz="1e-3" />
    </inertial>
  </link>

  <joint name="head-pan" type="continuous">
    <parent link="torso" />
    <child link="neck" />
    <origin rpy="0 0 0" xyz="0 0 0.0505" />
    <axis xyz="0 0 1" />
  </joint>

  <link name="neck">
    <visual>
      <origin rpy="0 0 0" xyz="0 0 0" />
      <geometry>
        <box size="0.02 0.02 0.02"/>
      </geometry>
    </visual>
    <inertial>
      <origin xyz="0 0 0" />
      <mass value="0.1"/>
      <inertia ixx="1e-4"  ixy="0.0"  ixz="0.0" iyy="1e-4" iyz="0.0" izz="1e-4" />
    </inertial>
  </link>

  <joint name="head-tilt" type="continuous">
    <parent link="neck" />
    <child link="head" />
    <origin rpy="0 0.785398163 0" xyz="0 0 0" />
    <axis xyz="0 -1 0" />
  </joint>

  <link name="head">
    <visual>
      <origin rpy="0 0 0" xyz="0 0 0.03"/>
      <geometry>
        <box size="0.03 0.03 0.06" />
      </geometry>
    </visual>
    <collision>
      <origin rpy="0 0 0" xyz="0 0 0.03"/>
      <geometry>
        <box size="0.03 0.03 0.06" />
      </geometry>
    </collision>
    <inertial>
      <origin xyz="0 0 0" />
      <mass value=".2"/>
      <inertia ixx="1e-3"  ixy="0.0"  ixz="0.0" iyy="1e-3" iyz="0.0" izz="1e-3" />
    </inertial>
  </link>

  <!-- Left Arm -->

  <joint name="shoulder-pitch-l" type="continuous">
    <parent link="torso" />
    <child link="shoulder-l" />
    <origin rpy="0 0 0" xyz="0 0.082 0" />
    <axis xyz="0 1 0" />
  </joint>

  <link name="shoulder-l">
    <visual>
      <origin rpy="0 0 0" xyz="0 0 0" />
      <geometry>
        <box size="0.02 0.02 0.02"/>
      </geometry>
    </visual>
    <inertial>
      <origin xyz="0 0 0" />
      <mass value="0.1"/>
      <inertia ixx="1e-4"  ixy="0.0"  ixz="0.0" iyy="1e-4" iyz="0.0" izz="1e-4" />
    </inertial>
  </link>

  <joint name="shoulder-roll-l" type="continuous">
    <parent link="shoulder-l" />
    <child link="upper-arm-l" />
    <origin rpy="0.785398163 0 0" xyz="0 0 -0.016" />
    <axis xyz="-1 0 0" />
  </joint>

  <link name="upper-arm-l">
    <visual>
      <origin rpy="0 0 0" xyz="0 0 -0.03" />
      <geometry>
        <box size="0.04 0.04 0.06"/>
      </geometry>
    </visual>
    <inertial>
      <origin xyz="0 0 0" />
      <mass value="0.1"/>
      <inertia ixx="1e-3"  ixy="0.0"  ixz="0.0" iyy="1e-3" iyz="0.0" izz="1e-3" />
    </inertial>
  </link>

  <joint name="elbow-l" type="continuous">
    <parent link="upper-arm-l" />
    <child link="lower-arm-l" />
    <origin rpy="0 -1.570796327 0" xyz="0.016 0 -0.06" />
    <axis xyz="0 1 0" />
  </joint>

  <link name="lower-arm-l">
    <visual>
      <origin rpy="0 0 0" xyz="-0.016 0 -0.03" />
      <geometry>
        <box size="0.04 0.04 0.06"/>
      </geometry>
    </visual>
    <inertial>
      <origin xyz="0 0 0" />
      <mass value="0.1"/>
      <inertia ixx="1e-3"  ixy="0.0"  ixz="0.0" iyy="1e-3" iyz="0.0" izz="1e-3" />
    </inertial>
  </link>

  <!-- Right Arm -->

  <joint name="shoulder-pitch-r" type="continuous">
    <parent link="torso" />
    <child link="shoulder-r" />
    <origin rpy="0 0 0" xyz="0 -0.082 0" />
    <axis xyz="0 -1 0" />
  </joint>

  <link name="shoulder-r">
    <visual>
      <origin rpy="0 0 0" xyz="0 0 0" />
      <geometry>
        <box size="0.02 0.02 0.02"/>
      </geometry>
    </visual>
    <inertial>
      <origin xyz="0 0 0" />
      <mass value="0.1"/>
      <inertia ixx="1e-4"  ixy="0.0"  ixz="0.0" iyy="1e-4" iyz="0.0" izz="1e-4" />
    </inertial>
  </link>

  <joint name="shoulder-roll-r" type="continuous">
    <parent link="shoulder-r" />
    <child link="upper-arm-r" />
    <origin rpy="-0.785398163 0 0" xyz="0 0 -0.016" />
    <axis xyz="-1 0 0" />
  </joint>

  <link name="upper-arm-r">
    <visual>
      <origin rpy="0 0 0" xyz="0 0 -0.03" />
      <geometry>
        <box size="0.04 0.04 0.06"/>
      </geometry>
    </visual>
    <inertial>
      <origin xyz="0 0 0" />
      <mass value=".1"/>
      <inertia ixx="1e-3"  ixy="0.0"  ixz="0.0" iyy="1e-3" iyz="0.0" izz="1e-3" />
    </inertial>
  </link>

  <joint name="elbow-r" type="continuous">
    <parent link="upper-arm-r" />
    <child link="lower-arm-r" />
    <origin rpy="0 -1.570796327 0" xyz="0.016 0 -0.06" />
    <axis xyz="0 -1 0" />
  </joint>

  <link name="lower-arm-r">
    <visual>
      <origin rpy="0 0 0" xyz="-0.016 0 -0.03" />
      <geometry>
        <box size="0.04 0.04 0.06"/>
      </geometry>
    </visual>
    <inertial>
      <origin xyz="0 0 0" />
      <mass value="0.1"/>
      <inertia ixx="1e-3"  ixy="0.0"  ixz="0.0" iyy="1e-3" iyz="0.0" izz="1e-3" />
    </inertial>
  </link>

  <!-- Left Leg -->

  <joint name="hip-yaw-l" type="continuous">
    <parent link="torso" />
    <child link="hip-bracket-l" />
    <origin rpy="0 0 0" xyz="-0.005 0.037 -0.1222" />
    <axis xyz="0 0 -1" />
  </joint>

  <link name="hip-bracket-l">
    <visual>
      <origin rpy="0 0 0" xyz="0 0 0" />
      <geometry>
        <box size="0.02 0.02 0.02"/>
      </geometry>
    </visual>
    <inertial>
      <origin xyz="0 0 0" />
      <mass value=".1"/>
      <inertia ixx="1e-4"  ixy="0.0"  ixz="0.0" iyy="1e-4" iyz="0.0" izz="1e-4" />
    </inertial>
  </link>

  <joint name="hip-roll-l" type="continuous">
    <parent link="hip-bracket-l" />
    <child link="buttock-l" />
    <origin rpy="0 0 0" xyz="0 0 0" />
    <axis xyz="-1 0 0" />
  </joint>

  <link name="buttock-l">
    <visual>
      <origin rpy="0 0 0" xyz="0 0 0" />
      <geometry>
        <box size="0.02 0.02 0.02"/>
      </geometry>
    </visual>
    <inertial>
      <origin xyz="0 0 0" />
      <mass value="0.1"/>
      <inertia ixx="1e-4"  ixy="0.0"  ixz="0.0" iyy="1e-4" iyz="0.0" izz="1e-4" />
    </inertial>
  </link>

  <joint name="hip-pitch-l" type="continuous">
    <parent link="buttock-l" />
    <child link="upper-leg-l" />
    <origin rpy="0 0 0" xyz="0 0 0" />
    <axis xyz="0 -1 0" />
  </joint>

  <link name="upper-leg-l">
    <visual>
      <origin rpy="0 0 0" xyz="0 0 -0.07" />
      <geometry>
        <box size="0.04 0.04 0.14"/>
      </geometry>
    </visual>
    <inertial>
      <origin xyz="0 0 0" />
      <mass value="0.1"/>
      <inertia ixx="1e-3"  ixy="0.0"  ixz="0.0" iyy="1e-3" iyz="0.0" izz="1e-3" />
    </inertial>
  </link>

  <joint name="knee-l" type="continuous">
    <parent link="upper-leg-l" />
    <child link="lower-leg-l" />
    <origin rpy="0 0 0" xyz="0 0 -0.14" />
    <axis xyz="0 -1 0" />
  </joint>

  <link name="lower-leg-l">
    <visual>
      <origin rpy="0 0 0" xyz="0 0 -0.07" />
      <geometry>
        <box size="0.04 0.04 0.14"/>
      </geometry>
    </visual>
    <inertial>
      <origin xyz="0 0 0" />
      <mass value="0.1"/>
      <inertia ixx="1e-3"  ixy="0.0"  ixz="0.0" iyy="1e-3" iyz="0.0" izz="1e-3" />
    </inertial>
  </link>

  <joint name="ankle-pitch-l" type="continuous">
    <parent link="lower-leg-l" />
    <child link="ankle-l" />
    <origin rpy="0 0 0" xyz="0 0 -0.14" />
    <axis xyz="0 1 0" />
  </joint>

  <link name="ankle-l">
    <visual>
      <origin rpy="0 0 0" xyz="0 0 0" />
      <geometry>
        <box size="0.02 0.02 0.02"/>
      </geometry>
    </visual>
    <inertial>
      <origin xyz="0 0 0" />
      <mass value="0.1"/>
      <inertia ixx="1e-4"  ixy="0.0"  ixz="0.0" iyy="1e-4" iyz="0.0" izz="1e-4" />
    </inertial>
  </link>

  <joint name="ankle-roll-l" type="continuous">
    <parent link="ankle-l" />
    <child link="foot-l" />
    <origin rpy="0 0 0" xyz="0 0 0" />
    <axis xyz="1 0 0" />
  </joint>

  <link name="foot-l">
    <visual>
      <origin rpy="0 0 0" xyz="0 0 -0.0335" />
      <geometry>
        <box size="0.12 0.05 0.02"/>
      </geometry>
    </visual>
    <inertial>
      <origin xyz="0 0 0" />
      <mass value="0.1"/>
      <inertia ixx="1e-3"  ixy="0.0"  ixz="0.0" iyy="1e-3" iyz="0.0" izz="1e-3" />
    </inertial>
  </link>

  <!-- Right Leg -->

  <joint name="hip-yaw-r" type="continuous">
    <parent link="torso" />
    <child link="hip-bracket-r" />
    <origin rpy="0 0 0" xyz="-0.005 -0.037 -0.1222" />
    <axis xyz="0 0 -1" />
  </joint>

  <link name="hip-bracket-r">
    <visual>
      <origin rpy="0 0 0" xyz="0 0 0" />
      <geometry>
        <box size="0.02 0.02 0.02"/>
      </geometry>
    </visual>
    <inertial>
      <origin xyz="0 0 0" />
      <mass value="0.1"/>
      <inertia ixx="1e-4"  ixy="0.0"  ixz="0.0" iyy="1e-4" iyz="0.0" izz="1e-4" />
    </inertial>
  </link>

  <joint name="hip-roll-r" type="continuous">
    <parent link="hip-bracket-r" />
    <child link="buttock-r" />
    <origin rpy="0 0 0" xyz="0 0 0" />
    <axis xyz="-1 0 0" />
  </joint>

  <link name="buttock-r">
    <visual>
      <origin rpy="0 0 0" xyz="0 0 0" />
      <geometry>
        <box size="0.02 0.02 0.02"/>
      </geometry>
    </visual>
    <inertial>
      <origin xyz="0 0 0" />
      <mass value="0.1"/>
      <inertia ixx="1e-4"  ixy="0.0"  ixz="0.0" iyy="1e-4" iyz="0.0" izz="1e-4" />
    </inertial>
  </link>

  <joint name="hip-pitch-r" type="continuous">
    <parent link="buttock-r" />
    <child link="upper-leg-r" />
    <origin rpy="0 0 0" xyz="0 0 0" />
    <axis xyz="0 1 0" />
  </joint>

  <link name="upper-leg-r">
    <visual>
      <origin rpy="0 0 0" xyz="0 0 -0.07" />
      <geometry>
        <box size="0.04 0.04 0.14"/>
      </geometry>
    </visual>
    <inertial>
      <origin xyz="0 0 0" />
      <mass value="0.1"/>
      <inertia ixx="1e-3"  ixy="0.0"  ixz="0.0" iyy="1e-3" iyz="0.0" izz="1e-3" />
    </inertial>
  </link>

  <joint name="knee-r" type="continuous">
    <parent link="upper-leg-r" />
    <child link="lower-leg-r" />
    <origin rpy="0 0 0" xyz="0 0 -0.14" />
    <axis xyz="0 1 0" />
  </joint>

  <link name="lower-leg-r">
    <visual>
      <origin rpy="0 0 0" xyz="0 0 -0.07" />
      <geometry>
        <box size="0.04 0.04 0.14"/>
      </geometry>
    </visual>
    <inertial>
      <origin xyz="0 0 0" />
      <mass value="0.1"/>
      <inertia ixx="1e-3"  ixy="0.0"  ixz="0.0" iyy="1e-3" iyz="0.0" izz="1e-3" />
    </inertial>
  </link>

  <joint name="ankle-pitch-r" type="continuous">
    <parent link="lower-leg-r" />
    <child link="ankle-r" />
    <origin rpy="0 0 0" xyz="0 0 -0.14" />
    <axis xyz="0 -1 0" />
  </joint>

  <link name="ankle-r">
    <visual>
      <origin rpy="0 0 0" xyz="0 0 0" />
      <geometry>
        <box size="0.02 0.02 0.02"/>
      </geometry>
    </visual>
    <inertial>
      <origin xyz="0 0 0" />
      <mass value="0.1"/>
      <inertia ixx="1e-4"  ixy="0.0"  ixz="0.0" iyy="1e-4" iyz="0.0" izz="1e-4" />
    </inertial>
  </link>

  <joint name="ankle-roll-r" type="continuous">
    <parent link="ankle-r" />
    <child link="foot-r" />
    <origin rpy="0 0 0" xyz="0 0 0" />
    <axis xyz="1 0 0" />
  </joint>

  <link name="foot-r">
    <visual>
      <origin rpy="0 0 0" xyz="0 0 -0.0335" />
      <geometry>
        <box size="0.12 0.05 0.02"/>
      </geometry>
    </visual>
    <inertial>
      <origin xyz="0 0 0" />
      <mass value="0.1"/>
      <inertia ixx="1e-4"  ixy="0.0"  ixz="0.0" iyy="1e-4" iyz="0.0" izz="1e-4" />
    </inertial>
  </link>

</robot>
