<?xml version="1.0" ?>

<robot name="boldbot" xmlns:xacro="http://www.ros.org/wiki/xacro">
  <xacro:macro name="mx28" params="name xyz rpy">
    <link name="${name}">
      <visual>
        <origin xyz="${xyz}" rpy="${rpy}" />
        <geometry>
          <mesh filename="/home/sander/src/boldbot/boldbot_description/meshes/mx28.stl" scale="0.001 0.001 0.001" />
        </geometry>
        <material name="DarkGrey">
          <color rgba="0.20 0.20 0.20 1.0"/>
        </material>
      </visual>
      <collision>
        <origin xyz="${xyz}" rpy="${rpy}" />
        <geometry>
          <mesh filename="/home/sander/src/boldbot/boldbot_description/meshes/mx28.stl" scale="0.001 0.001 0.001" />
        </geometry>
      </collision>
      <inertial>
        <origin xyz="${xyz}" rpy="${rpy}" />
        <mass value="0.072"/>
        <inertia ixx="0.00002292366"  ixy="0.0"  ixz="0.0" iyy="0.00001516566" iyz="0.0" izz="0.00002296632" />
      </inertial>
    </link>

    <gazebo reference="${name}">
      <material>Gazebo/Grey</material>
    </gazebo>
  </xacro:macro>
  
  <!-- dummy first link, directly connects with torso -->
  <link name="base_link" />

  <joint name="base_joint" type="fixed">
    <child link="torso"/>
    <parent link="base_link"/>
    <origin xyz="0 0 0" rpy="0 0 0" />
  </joint>

  <link name="torso">
    <visual>
      <origin rpy="0 0 0" xyz="0 0 0" />
      <geometry>
        <box size="0.1 0.109 0.045"/>
      </geometry>
    </visual>
    <collision>
      <origin rpy="0 0 0" xyz="0 0 0" />
      <geometry>
        <box size="0.1 0.109 0.045"/>
      </geometry>
    </collision>
    <inertial>
      <origin xyz="0 0 0" />
      <mass value="0.1"/>
      <inertia ixx="1e-3"  ixy="0.0"  ixz="0.0" iyy="1e-3" iyz="0.0" izz="1e-3" />
    </inertial>
  </link>

  <joint name="torso-mx28-head-pan" type="fixed">
    <parent link="torso" />
    <child link="mx28-head-pan" />
    <origin rpy="0 0 0" xyz="0.02 0 0.045" />
  </joint>

  <xacro:mx28 name="mx28-head-pan" xyz="0 0 0" rpy="0 0 3.141592654"/>

  <joint name="head-pan" type="revolute">
    <parent link="mx28-head-pan" />
    <child link="neck" />
    <origin rpy="0 0 0" xyz="0 0 0" />
    <axis xyz="0 0 1" />
    <limit effort="2.8" velocity="5.6548668" lower="-2.6179939" upper="2.6179939" />
  </joint>

  <link name="neck">
    <visual>
      <origin rpy="0 0 0" xyz="0 0 0.03" />
      <geometry>
        <box size="0.01 0.01 0.01"/>
      </geometry>
    </visual>
    <inertial>
      <origin xyz="0 0 0" />
      <mass value="1e-3"/>
      <inertia ixx="1e-4"  ixy="0.0"  ixz="0.0" iyy="1e-4" iyz="0.0" izz="1e-4" />
    </inertial>
  </link>

  <joint name="head-tilt" type="revolute">
    <parent link="neck" />
    <child link="mx28-head-tilt" />
    <origin xyz="0 0 0.05" />
    <axis xyz="0 1 0" />
    <limit effort="2.8" velocity="5.6548668" lower="-2.6179939" upper="2.6179939" />
  </joint>

  <xacro:mx28 name="mx28-head-tilt" xyz="0 0 0" rpy="0 -1.570796327 -1.570796327"/>
  
  <joint name="head-tilt-head" type="fixed">
    <parent link="mx28-head-tilt" />
    <child link="head" />
    <origin rpy="0 0 0" xyz="0 0 0.065" />
  </joint>

  <link name="head">
    <visual>
      <origin rpy="0 0 0" xyz="0 0 0"/>
      <geometry>
        <box size="0.05 0.1 0.04" />
      </geometry>
    </visual>
    <collision>
      <origin rpy="0 0 0" xyz="0 0 0"/>
      <geometry>
        <box size="0.05 0.1 0.04" />
      </geometry>
    </collision>
    <inertial>
      <origin xyz="0 0 0" />
      <mass value=".2"/>
      <inertia ixx="1e-3"  ixy="0.0"  ixz="0.0" iyy="1e-3" iyz="0.0" izz="1e-3" />
    </inertial>
  </link>

  <!-- Left Arm -->

  <joint name="torso-mx28-shoulder-pitch-l" type="fixed">
    <parent link="torso" />
    <child link="mx28-shoulder-pitch-l" />
    <origin xyz="0.02 0.04 0.045" />
  </joint>

  <xacro:mx28 name="mx28-shoulder-pitch-l" xyz="0 0 0" rpy="1.570796327 0 3.141592654"/>

  <joint name="shoulder-pitch-l" type="revolute">
    <parent link="mx28-shoulder-pitch-l" />
    <child link="shoulder-l" />
    <origin rpy="0 0 0" xyz="0 0 0" />
    <axis xyz="0 1 0" />
    <limit effort="2.8" velocity="5.6548668" lower="-2.6179939" upper="2.6179939" />
  </joint>

  <link name="shoulder-l">
    <visual>
      <origin rpy="0 0 0" xyz="0 0.021 -0.008" />
      <geometry>
        <box size="0.01 0.01 0.01"/>
      </geometry>
    </visual>
    <inertial>
      <origin xyz="0 0 0" />
      <mass value="0.1"/>
      <inertia ixx="1e-4"  ixy="0.0"  ixz="0.0" iyy="1e-4" iyz="0.0" izz="1e-4" />
    </inertial>
  </link>

  <joint name="shoulder-roll-l" type="revolute">
    <parent link="shoulder-l" />
    <child link="mx28-shoulder-roll-l" />
    <origin rpy="0.785398163 0 0" xyz="0 0.042 -0.016" />
    <axis xyz="-1 0 0" />
    <limit effort="2.8" velocity="5.6548668" lower="-2.6179939" upper="2.6179939" />
  </joint>

  <xacro:mx28 name="mx28-shoulder-roll-l" xyz="0 0 0" rpy="0 1.570796327 0"/>

  <joint name="mx28-shoulder-roll-l-mx28-elbow-l" type="fixed">
    <parent link="mx28-shoulder-roll-l" />
    <child link="mx28-elbow-l" />
    <origin xyz="0.016 0 -0.06" />
  </joint>

  <xacro:mx28 name="mx28-elbow-l" xyz="0 0 0" rpy="1.570796327 0 3.141592654"/>
  
  <joint name="elbow-l" type="revolute">
    <parent link="mx28-elbow-l" />
    <child link="lower-arm-l" />
    <origin xyz="0 0 0" rpy="0 0 0"/>
    <axis xyz="0 1 0" />
    <limit effort="2.8" velocity="5.6548668" lower="-2.6179939" upper="2.6179939" />
  </joint>

  <link name="lower-arm-l">
    <visual>
      <origin rpy="1.570796327 0 0" xyz="0.055 0.02 -0.02" />
      <geometry>
        <mesh filename="/home/sander/src/boldbot/boldbot_description/meshes/armcover.stl" scale="0.001 0.001 0.001"/>
      </geometry>
    </visual>
    <collision>
      <origin rpy="1.570796327 0 0" xyz="0.055 0.02 -0.02" />
      <geometry>
        <mesh filename="/home/sander/src/boldbot/boldbot_description/meshes/armcover.stl" scale="0.001 0.001 0.001"/>
      </geometry>
    </collision>
    <inertial>
      <origin xyz="0 0 0" />
      <mass value="0.1"/>
      <inertia ixx="1e-3"  ixy="0.0"  ixz="0.0" iyy="1e-3" iyz="0.0" izz="1e-3" />
    </inertial>
  </link>

  <!-- Right Arm -->

  <joint name="torso-mx28-shoulder-pitch-r" type="fixed">
    <parent link="torso" />
    <child link="mx28-shoulder-pitch-r" />
    <origin xyz="0.02 -0.04 0.045" />
  </joint>

  <xacro:mx28 name="mx28-shoulder-pitch-r" xyz="0 0 0" rpy="-1.570796327 0 3.141592654"/>

  <joint name="shoulder-pitch-r" type="continuous">
    <parent link="torso" />
    <child link="shoulder-r" />
    <origin rpy="0 0 0" xyz="0 -0.082 0" />
    <axis xyz="0 -1 0" />
    <limit effort="2.8" velocity="5.6548668" lower="-2.6179939" upper="2.6179939" />
  </joint>

  <link name="shoulder-r">
    <visual>
      <origin rpy="0 0 0" xyz="0 0 0" />
      <geometry>
        <box size="0.02 0.02 0.02"/>
      </geometry>
    </visual>
    <inertial>
      <origin xyz="0 0 0" />
      <mass value="0.1"/>
      <inertia ixx="1e-4"  ixy="0.0"  ixz="0.0" iyy="1e-4" iyz="0.0" izz="1e-4" />
    </inertial>
  </link>

  <joint name="shoulder-roll-r" type="continuous">
    <parent link="shoulder-r" />
    <child link="upper-arm-r" />
    <origin rpy="-0.785398163 0 0" xyz="0 0 -0.016" />
    <axis xyz="-1 0 0" />
    <limit effort="2.8" velocity="5.6548668" lower="-2.6179939" upper="2.6179939" />
  </joint>

  <link name="upper-arm-r">
    <visual>
      <origin rpy="0 0 0" xyz="0 0 -0.03" />
      <geometry>
        <box size="0.04 0.04 0.06"/>
      </geometry>
    </visual>
    <collision>
      <origin rpy="0 0 0" xyz="0 0 -0.03" />
      <geometry>
        <box size="0.04 0.04 0.06"/>
      </geometry>
    </collision>
    <inertial>
      <origin xyz="0 0 0" />
      <mass value=".1"/>
      <inertia ixx="1e-3"  ixy="0.0"  ixz="0.0" iyy="1e-3" iyz="0.0" izz="1e-3" />
    </inertial>
  </link>

  <joint name="elbow-r" type="continuous">
    <parent link="upper-arm-r" />
    <child link="lower-arm-r" />
    <origin rpy="0 -1.570796327 0" xyz="0.016 0 -0.06" />
    <axis xyz="0 -1 0" />
    <limit effort="2.8" velocity="5.6548668" lower="-2.6179939" upper="2.6179939" />
  </joint>

  <link name="lower-arm-r">
    <visual>
      <origin rpy="0 0 0" xyz="-0.016 0 -0.03" />
      <geometry>
        <box size="0.04 0.04 0.06"/>
      </geometry>
    </visual>
    <collision>
      <origin rpy="0 0 0" xyz="-0.016 0 -0.03" />
      <geometry>
        <box size="0.04 0.04 0.06"/>
      </geometry>
    </collision>
    <inertial>
      <origin xyz="0 0 0" />
      <mass value="0.1"/>
      <inertia ixx="1e-3"  ixy="0.0"  ixz="0.0" iyy="1e-3" iyz="0.0" izz="1e-3" />
    </inertial>
  </link>

  <!-- Left Leg -->

  <joint name="hip-yaw-l" type="continuous">
    <parent link="torso" />
    <child link="hip-bracket-l" />
    <origin rpy="0 0 0" xyz="-0.005 0.037 -0.1222" />
    <axis xyz="0 0 -1" />
    <limit effort="2.8" velocity="5.6548668" lower="-2.6179939" upper="2.6179939" />
  </joint>

  <link name="hip-bracket-l">
    <visual>
      <origin rpy="0 0 0" xyz="0 0 0" />
      <geometry>
        <box size="0.02 0.02 0.02"/>
      </geometry>
    </visual>
    <inertial>
      <origin xyz="0 0 0" />
      <mass value=".1"/>
      <inertia ixx="1e-4"  ixy="0.0"  ixz="0.0" iyy="1e-4" iyz="0.0" izz="1e-4" />
    </inertial>
  </link>

  <joint name="hip-roll-l" type="continuous">
    <parent link="hip-bracket-l" />
    <child link="buttock-l" />
    <origin rpy="0 0 0" xyz="0 0 0" />
    <axis xyz="-1 0 0" />
    <limit effort="2.8" velocity="5.6548668" lower="-2.6179939" upper="2.6179939" />
  </joint>

  <link name="buttock-l">
    <visual>
      <origin rpy="0 0 0" xyz="0 0 0" />
      <geometry>
        <box size="0.02 0.02 0.02"/>
      </geometry>
    </visual>
    <inertial>
      <origin xyz="0 0 0" />
      <mass value="0.1"/>
      <inertia ixx="1e-4"  ixy="0.0"  ixz="0.0" iyy="1e-4" iyz="0.0" izz="1e-4" />
    </inertial>
  </link>

  <joint name="hip-pitch-l" type="continuous">
    <parent link="buttock-l" />
    <child link="upper-leg-l" />
    <origin rpy="0 0 0" xyz="0 0 0" />
    <axis xyz="0 -1 0" />
    <limit effort="2.8" velocity="5.6548668" lower="-2.6179939" upper="2.6179939" />
  </joint>

  <link name="upper-leg-l">
    <visual>
      <origin rpy="0 0 0" xyz="0 0 -0.07" />
      <geometry>
        <box size="0.04 0.04 0.14"/>
      </geometry>
    </visual>
    <collision>
      <origin rpy="0 0 0" xyz="0 0 -0.07" />
      <geometry>
        <box size="0.04 0.04 0.14"/>
      </geometry>
    </collision>
    <inertial>
      <origin xyz="0 0 0" />
      <mass value="0.1"/>
      <inertia ixx="1e-3"  ixy="0.0"  ixz="0.0" iyy="1e-3" iyz="0.0" izz="1e-3" />
    </inertial>
  </link>

  <joint name="knee-l" type="continuous">
    <parent link="upper-leg-l" />
    <child link="lower-leg-l" />
    <origin rpy="0 0 0" xyz="0 0 -0.14" />
    <axis xyz="0 -1 0" />
    <limit effort="2.8" velocity="5.6548668" lower="-2.6179939" upper="2.6179939" />
  </joint>

  <link name="lower-leg-l">
    <visual>
      <origin rpy="0 0 0" xyz="0 0 -0.07" />
      <geometry>
        <box size="0.04 0.04 0.14"/>
      </geometry>
    </visual>
    <collision>
      <origin rpy="0 0 0" xyz="0 0 -0.07" />
      <geometry>
        <box size="0.04 0.04 0.14"/>
      </geometry>
    </collision>
    <inertial>
      <origin xyz="0 0 0" />
      <mass value="0.1"/>
      <inertia ixx="1e-3"  ixy="0.0"  ixz="0.0" iyy="1e-3" iyz="0.0" izz="1e-3" />
    </inertial>
  </link>

  <joint name="ankle-pitch-l" type="continuous">
    <parent link="lower-leg-l" />
    <child link="ankle-l" />
    <origin rpy="0 0 0" xyz="0 0 -0.14" />
    <axis xyz="0 1 0" />
    <limit effort="2.8" velocity="5.6548668" lower="-2.6179939" upper="2.6179939" />
  </joint>

  <link name="ankle-l">
    <visual>
      <origin rpy="0 0 0" xyz="0 0 0" />
      <geometry>
        <box size="0.02 0.02 0.02"/>
      </geometry>
    </visual>
    <inertial>
      <origin xyz="0 0 0" />
      <mass value="0.1"/>
      <inertia ixx="1e-4"  ixy="0.0"  ixz="0.0" iyy="1e-4" iyz="0.0" izz="1e-4" />
    </inertial>
  </link>

  <joint name="ankle-roll-l" type="continuous">
    <parent link="ankle-l" />
    <child link="foot-l" />
    <origin rpy="0 0 0" xyz="0 0 0" />
    <axis xyz="1 0 0" />
    <limit effort="2.8" velocity="5.6548668" lower="-2.6179939" upper="2.6179939" />
  </joint>

  <link name="foot-l">
    <visual>
      <origin rpy="0 0 0" xyz="0 0 -0.0335" />
      <geometry>
        <box size="0.12 0.05 0.02"/>
      </geometry>
    </visual>
    <collision>
      <origin rpy="0 0 0" xyz="0 0 -0.0335" />
      <geometry>
        <box size="0.12 0.05 0.02"/>
      </geometry>
    </collision>
    <inertial>
      <origin xyz="0 0 0" />
      <mass value="0.1"/>
      <inertia ixx="1e-3"  ixy="0.0"  ixz="0.0" iyy="1e-3" iyz="0.0" izz="1e-3" />
    </inertial>
  </link>

  <!-- Right Leg -->

  <joint name="hip-yaw-r" type="continuous">
    <parent link="torso" />
    <child link="hip-bracket-r" />
    <origin rpy="0 0 0" xyz="-0.005 -0.037 -0.1222" />
    <axis xyz="0 0 -1" />
    <limit effort="2.8" velocity="5.6548668" lower="-2.6179939" upper="2.6179939" />
  </joint>

  <link name="hip-bracket-r">
    <visual>
      <origin rpy="0 0 0" xyz="0 0 0" />
      <geometry>
        <box size="0.02 0.02 0.02"/>
      </geometry>
    </visual>
    <inertial>
      <origin xyz="0 0 0" />
      <mass value="0.1"/>
      <inertia ixx="1e-4"  ixy="0.0"  ixz="0.0" iyy="1e-4" iyz="0.0" izz="1e-4" />
    </inertial>
  </link>

  <joint name="hip-roll-r" type="continuous">
    <parent link="hip-bracket-r" />
    <child link="buttock-r" />
    <origin rpy="0 0 0" xyz="0 0 0" />
    <axis xyz="-1 0 0" />
    <limit effort="2.8" velocity="5.6548668" lower="-2.6179939" upper="2.6179939" />
  </joint>

  <link name="buttock-r">
    <visual>
      <origin rpy="0 0 0" xyz="0 0 0" />
      <geometry>
        <box size="0.02 0.02 0.02"/>
      </geometry>
    </visual>
    <inertial>
      <origin xyz="0 0 0" />
      <mass value="0.1"/>
      <inertia ixx="1e-4"  ixy="0.0"  ixz="0.0" iyy="1e-4" iyz="0.0" izz="1e-4" />
    </inertial>
  </link>

  <joint name="hip-pitch-r" type="continuous">
    <parent link="buttock-r" />
    <child link="upper-leg-r" />
    <origin rpy="0 0 0" xyz="0 0 0" />
    <axis xyz="0 1 0" />
    <limit effort="2.8" velocity="5.6548668" lower="-2.6179939" upper="2.6179939" />
  </joint>

  <link name="upper-leg-r">
    <visual>
      <origin rpy="0 0 0" xyz="0 0 -0.07" />
      <geometry>
        <box size="0.04 0.04 0.14"/>
      </geometry>
    </visual>
    <collision>
      <origin rpy="0 0 0" xyz="0 0 -0.07" />
      <geometry>
        <box size="0.04 0.04 0.14"/>
      </geometry>
    </collision>
    <inertial>
      <origin xyz="0 0 0" />
      <mass value="0.1"/>
      <inertia ixx="1e-3"  ixy="0.0"  ixz="0.0" iyy="1e-3" iyz="0.0" izz="1e-3" />
    </inertial>
  </link>

  <joint name="knee-r" type="continuous">
    <parent link="upper-leg-r" />
    <child link="lower-leg-r" />
    <origin rpy="0 0 0" xyz="0 0 -0.14" />
    <axis xyz="0 1 0" />
    <limit effort="2.8" velocity="5.6548668" lower="-2.6179939" upper="2.6179939" />
  </joint>

  <link name="lower-leg-r">
    <visual>
      <origin rpy="0 0 0" xyz="0 0 -0.07" />
      <geometry>
        <box size="0.04 0.04 0.14"/>
      </geometry>
    </visual>
    <collision>
      <origin rpy="0 0 0" xyz="0 0 -0.07" />
      <geometry>
        <box size="0.04 0.04 0.14"/>
      </geometry>
    </collision>
    <inertial>
      <origin xyz="0 0 0" />
      <mass value="0.1"/>
      <inertia ixx="1e-3"  ixy="0.0"  ixz="0.0" iyy="1e-3" iyz="0.0" izz="1e-3" />
    </inertial>
  </link>

  <joint name="ankle-pitch-r" type="continuous">
    <parent link="lower-leg-r" />
    <child link="ankle-r" />
    <origin rpy="0 0 0" xyz="0 0 -0.14" />
    <axis xyz="0 -1 0" />
    <limit effort="2.8" velocity="5.6548668" lower="-2.6179939" upper="2.6179939" />
  </joint>

  <link name="ankle-r">
    <visual>
      <origin rpy="0 0 0" xyz="0 0 0" />
      <geometry>
        <box size="0.02 0.02 0.02"/>
      </geometry>
    </visual>
    <inertial>
      <origin xyz="0 0 0" />
      <mass value="0.1"/>
      <inertia ixx="1e-4"  ixy="0.0"  ixz="0.0" iyy="1e-4" iyz="0.0" izz="1e-4" />
    </inertial>
  </link>

  <joint name="ankle-roll-r" type="continuous">
    <parent link="ankle-r" />
    <child link="foot-r" />
    <origin rpy="0 0 0" xyz="0 0 0" />
    <axis xyz="1 0 0" />
    <limit effort="2.8" velocity="5.6548668" lower="-2.6179939" upper="2.6179939" />
  </joint>

  <link name="foot-r">
    <visual>
      <origin rpy="0 0 0" xyz="0 0 -0.0335" />
      <geometry>
        <box size="0.12 0.05 0.02"/>
      </geometry>
    </visual>
    <collision>
      <origin rpy="0 0 0" xyz="0 0 -0.0335" />
      <geometry>
        <box size="0.12 0.05 0.02"/>
      </geometry>
    </collision>
    <inertial>
      <origin xyz="0 0 0" />
      <mass value="0.1"/>
      <inertia ixx="1e-4"  ixy="0.0"  ixz="0.0" iyy="1e-4" iyz="0.0" izz="1e-4" />
    </inertial>
  </link>

</robot>
